{"uuid": "797034f6-b13e-43d0-89c6-66652ae61810", "children": ["64e4d27f-2c78-43ca-b603-4aa7e7762a3f", "037eebf3-67d2-4234-b0d4-3219a2dce163", "5607c9e5-1f3f-4ba1-8ded-bc6d83e308eb", "9aac6d97-4b60-40ee-bfa9-42306205b334", "ec1183b3-56a0-4ba7-84c4-b34812953203", "52026215-3f3e-4587-8e46-f7b4e81fcf6e", "e1931e3c-656f-4d5d-ad88-16d7fe9abfcc", "66e03848-a862-4b41-9de3-926dca1869aa", "f0a13ea6-d133-4e10-95c4-ee326bd27892", "b859b711-b6a1-4e5e-a075-38f69439a09d", "7b663790-0a37-4e3d-8f9e-55b08663765d", "c9c187c5-67a1-46c9-8118-2c1df8b018af", "a81516f2-219c-43cb-8487-c5d78bcff0c5", "00ff0bea-95a2-4f7b-a1e3-bb8fed143dde", "96c914de-15d2-4a14-9aca-3bb162372766"], "befores": [{"name": "work_login_init", "status": "broken", "statusDetails": {"message": "requests.exceptions.SSLError: HTTPSConnectionPool(host='www.wanandroid.com', port=443): Max retries exceeded with url: /user/login (Caused by SSLError(SSLCertVerificationError(1, '[SSL: CERTIFICATE_VERIFY_FAILED] certificate verify failed: unable to get local issuer certificate (_ssl.c:1129)')))\n", "trace": "  File \"C:\\work\\Study\\pytest-auto-api2\\venv\\lib\\site-packages\\pluggy\\_callers.py\", line 39, in _multicall\n    res = hook_impl.function(*args)\n  File \"C:\\work\\Study\\pytest-auto-api2\\venv\\lib\\site-packages\\_pytest\\fixtures.py\", line 1111, in pytest_fixture_setup\n    result = call_fixture_func(fixturefunc, request, kwargs)\n  File \"C:\\work\\Study\\pytest-auto-api2\\venv\\lib\\site-packages\\_pytest\\fixtures.py\", line 890, in call_fixture_func\n    fixture_result = fixturefunc(**kwargs)\n  File \"C:\\work\\Study\\pytest-auto-api2\\test_case\\conftest.py\", line 69, in work_login_init\n    res = RequestControl().http_request(login_yaml)\n  File \"C:\\work\\Study\\pytest-auto-api2\\utils\\logUtils\\logDecoratorl.py\", line 22, in swapper\n    res = func(*args, **kwargs)\n  File \"C:\\work\\Study\\pytest-auto-api2\\utils\\logUtils\\runTimeDecoratorl.py\", line 22, in swapper\n    res = func(*args, **kwargs)\n  File \"C:\\work\\Study\\pytest-auto-api2\\utils\\requestsUtils\\requestControl.py\", line 150, in http_request\n    res = requests.request(method=_method, url=yaml_data[YAMLDate.URL.value], data=_data, headers=_headers,\n  File \"C:\\work\\Study\\pytest-auto-api2\\venv\\lib\\site-packages\\requests\\api.py\", line 61, in request\n    return session.request(method=method, url=url, **kwargs)\n  File \"C:\\work\\Study\\pytest-auto-api2\\venv\\lib\\site-packages\\requests\\sessions.py\", line 529, in request\n    resp = self.send(prep, **send_kwargs)\n  File \"C:\\work\\Study\\pytest-auto-api2\\venv\\lib\\site-packages\\requests\\sessions.py\", line 645, in send\n    r = adapter.send(request, **kwargs)\n  File \"C:\\work\\Study\\pytest-auto-api2\\venv\\lib\\site-packages\\requests\\adapters.py\", line 517, in send\n    raise SSLError(e, request=request)\n"}, "start": 1649684226141, "stop": 1649684227289}], "start": 1649684226141, "stop": 1649684235533}